Workbook
Name Slicer_Brand_Cleaned: #N/A
Name Slicer_Country: #N/A
Name Slicer_Months: #N/A
Name Slicer_Product_Cleaned: #N/A

Sheet Dashboard

Sheet Shoe Sales (Original)
A1: Date | B1: Product | C1: Category | D1: Color | E1: Brand | F1: Country | G1: Quantity | H1: Payment Type
A2: 46161 | B2: monk straps | C2: Formal | D2: Red | E2: Nike | F2: Uganda | G2: 7 | H2: Bank Transfer
A3: 46199 | B3: loafers | C3: Formal | D3: Black | E3: nike | F3: Uganda | G3: 1 | H3: Card
A4: 46172 | B4: Derby | C4: FORMAL | D4: Green | E4: clarks | F4: Nigeria | G4: 7 | H4: Bank Transfer
A5: 46214 | B5: boots | C5: UTILITY | D5: Black | E5: nike | F5: Canada | G5: 6 | H5: Bank Transfer
A6: 46130 | B6: BOOTS | C6: casual | D6: Red | E6: CLARKS | F6: UK | G6: 6 | H6: Bank Transfer
A7: 46093 | B7: Canvas | C7: Utility | D7: Blue | E7: NIKE | F7: Ghana | G7: 6 | H7: Card
A8: 46191 | B8: canvas | C8: Formal | D8: Green | E8: clarks | F8: USA | G8: 13 | H8: Cash
A9: 46212 | B9: monk straps | C9: Formal | D9: Brown | E9: timberland | F9: USA | G9: 12 | H9: Cash
A10: 46038 | B10: Derby | C10: formal | D10: Green | E10: clarks | F10: Australia | G10: 10 | H10: Cash
A11: 46182 | B11: OXFORD | C11: Formal | D11: Black | E11: clarks | F11: Cyprus | G11: 15 | H11: Mobile Money
A12: 46132 | B12: BOOTS | C12: Formal | D12: Brown | E12: Clarks | F12: India | G12: 8 | H12: Bank Transfer
A13: 46097 | B13: loafers | C13: casual | D13: Green | E13: Clarks | F13: Australia | G13: 9 | H13: Cash
... A501: 46218 | B501: Derby | C501: casual | D501: Red | E501: CLARKS | F501: Germany | G501: 4 | H501: Bank Transfer

Sheet Cleaned
A1: Date | B1: Product | C1: Product Cleaned | D1: Category | E1: Category Cleaned | F1: Color | G1: Brand | H1: Brand Cleaned | I1: Country | J1: Quantity | K1: Payment Type | L1: Sell Price | M1: xlookup price | N1: Cost Price | O1: Revenue | P1: Cost | Q1: Profit | R1: Profit Margin | S1: Brand count | T1: Months
A2: 46161 | B2: monk straps | C2: =TRIM(PROPER(ShoeSales[[#This Row],[Product]])) -> Monk Straps | D2: Formal | E2: =UPPER(ShoeSales[[#This Row],[Category]]) -> FORMAL | F2: Red | G2: Nike | H2: =PROPER(ShoeSales[[#This Row],[Brand]]) -> Nike | I2: Uganda | J2: 7 | K2: Bank Transfer | L2: =VLOOKUP(ShoeSales[[#This Row],[Product Cleaned]],Price!$A$2:$C$9,2,FALSE) -> 89 | M2: =_xlfn.XLOOKUP(ShoeSales[[#This Row],[Product Cleaned]],Price!$A$2:$A$9,Price!$B$2:$B$9) -> 89 | N2: =_xlfn.XLOOKUP(ShoeSales[[#This Row],[Product Cleaned]],Price!$A$2:$A$9,Price!$C$2:$C$9) -> 47 | O2: =ShoeSales[[#This Row],[Sell Price]]*ShoeSales[[#This Row],[Quantity]] -> 623 | P2: =ShoeSales[[#This Row],[Quantity]]*ShoeSales[[#This Row],[Cost Price]] -> 329 | Q2: =ShoeSales[[#This Row],[Revenue]]-ShoeSales[[#This Row],[Cost]] -> 294 | R2: =ShoeSales[[#This Row],[Profit]]/ShoeSales[[#This Row],[Revenue]] -> 0.47191011 | S2: Nike | T2: =UPPER(TEXT(ShoeSales[[#This Row],[Date]], "mmm")) -> MAY
A3: 46199 | B3: loafers | C3: =TRIM(PROPER(ShoeSales[[#This Row],[Product]])) -> Loafers | D3: Formal | E3: =UPPER(ShoeSales[[#This Row],[Category]]) -> FORMAL | F3: Black | G3: nike | H3: =PROPER(ShoeSales[[#This Row],[Brand]]) -> Nike | I3: Uganda | J3: 1 | K3: Card | L3: =VLOOKUP(ShoeSales[[#This Row],[Product Cleaned]],Price!$A$2:$C$9,2,FALSE) -> 54 | M3: =_xlfn.XLOOKUP(ShoeSales[[#This Row],[Product Cleaned]],Price!$A$2:$A$9,Price!$B$2:$B$9) -> 54 | N3: =_xlfn.XLOOKUP(ShoeSales[[#This Row],[Product Cleaned]],Price!$A$2:$A$9,Price!$C$2:$C$9) -> 28 | O3: =ShoeSales[[#This Row],[Sell Price]]*ShoeSales[[#This Row],[Quantity]] -> 54 | P3: =ShoeSales[[#This Row],[Quantity]]*ShoeSales[[#This Row],[Cost Price]] -> 28 | Q3: =ShoeSales[[#This Row],[Revenue]]-ShoeSales[[#This Row],[Cost]] -> 26 | R3: =ShoeSales[[#This Row],[Profit]]/ShoeSales[[#This Row],[Revenue]] -> 0.48148148 | S3: Clarks | T3: =UPPER(TEXT(ShoeSales[[#This Row],[Date]], "mmm")) -> JUN
A4: 46172 | B4: Derby | C4: =TRIM(PROPER(ShoeSales[[#This Row],[Product]])) -> Derby | D4: FORMAL | E4: =UPPER(ShoeSales[[#This Row],[Category]]) -> FORMAL | F4: Green | G4: clarks | H4: =PROPER(ShoeSales[[#This Row],[Brand]]) -> Clarks | I4: Nigeria | J4: 7 | K4: Bank Transfer | L4: =VLOOKUP(ShoeSales[[#This Row],[Product Cleaned]],Price!$A$2:$C$9,2,FALSE) -> 32 | M4: =_xlfn.XLOOKUP(ShoeSales[[#This Row],[Product Cleaned]],Price!$A$2:$A$9,Price!$B$2:$B$9) -> 32 | N4: =_xlfn.XLOOKUP(ShoeSales[[#This Row],[Product Cleaned]],Price!$A$2:$A$9,Price!$C$2:$C$9) -> 14 | O4: =ShoeSales[[#This Row],[Sell Price]]*ShoeSales[[#This Row],[Quantity]] -> 224 | P4: =ShoeSales[[#This Row],[Quantity]]*ShoeSales[[#This Row],[Cost Price]] -> 98 | Q4: =ShoeSales[[#This Row],[Revenue]]-ShoeSales[[#This Row],[Cost]] -> 126 | R4: =ShoeSales[[#This Row],[Profit]]/ShoeSales[[#This Row],[Revenue]] -> 0.5625 | S4: Timberland | T4: =UPPER(TEXT(ShoeSales[[#This Row],[Date]], "mmm")) -> MAY
A5: 46214 | B5: boots | C5: =TRIM(PROPER(ShoeSales[[#This Row],[Product]])) -> Boots | D5: UTILITY | E5: =UPPER(ShoeSales[[#This Row],[Category]]) -> UTILITY | F5: Black | G5: nike | H5: =PROPER(ShoeSales[[#This Row],[Brand]]) -> Nike | I5: Canada | J5: 6 | K5: Bank Transfer | L5: =VLOOKUP(ShoeSales[[#This Row],[Product Cleaned]],Price!$A$2:$C$9,2,FALSE) -> 76 | M5: =_xlfn.XLOOKUP(ShoeSales[[#This Row],[Product Cleaned]],Price!$A$2:$A$9,Price!$B$2:$B$9) -> 76 | N5: =_xlfn.XLOOKUP(ShoeSales[[#This Row],[Product Cleaned]],Price!$A$2:$A$9,Price!$C$2:$C$9) -> 39 | O5: =ShoeSales[[#This Row],[Sell Price]]*ShoeSales[[#This Row],[Quantity]] -> 456 | P5: =ShoeSales[[#This Row],[Quantity]]*ShoeSales[[#This Row],[Cost Price]] -> 234 | Q5: =ShoeSales[[#This Row],[Revenue]]-ShoeSales[[#This Row],[Cost]] -> 222 | R5: =ShoeSales[[#This Row],[Profit]]/ShoeSales[[#This Row],[Revenue]] -> 0.48684211 | S5: Zara | T5: =UPPER(TEXT(ShoeSales[[#This Row],[Date]], "mmm")) -> JUL
A6: 46130 | B6: BOOTS | C6: =TRIM(PROPER(ShoeSales[[#This Row],[Product]])) -> Boots | D6: casual | E6: =UPPER(ShoeSales[[#This Row],[Category]]) -> CASUAL | F6: Red | G6: CLARKS | H6: =PROPER(ShoeSales[[#This Row],[Brand]]) -> Clarks | I6: UK | J6: 6 | K6: Bank Transfer | L6: =VLOOKUP(ShoeSales[[#This Row],[Product Cleaned]],Price!$A$2:$C$9,2,FALSE) -> 76 | M6: =_xlfn.XLOOKUP(ShoeSales[[#This Row],[Product Cleaned]],Price!$A$2:$A$9,Price!$B$2:$B$9) -> 76 | N6: =_xlfn.XLOOKUP(ShoeSales[[#This Row],[Product Cleaned]],Price!$A$2:$A$9,Price!$C$2:$C$9) -> 39 | O6: =ShoeSales[[#This Row],[Sell Price]]*ShoeSales[[#This Row],[Quantity]] -> 456 | P6: =ShoeSales[[#This Row],[Quantity]]*ShoeSales[[#This Row],[Cost Price]] -> 234 | Q6: =ShoeSales[[#This Row],[Revenue]]-ShoeSales[[#This Row],[Cost]] -> 222 | R6: =ShoeSales[[#This Row],[Profit]]/ShoeSales[[#This Row],[Revenue]] -> 0.48684211 | S6: Steve Madden | T6: =UPPER(TEXT(ShoeSales[[#This Row],[Date]], "mmm")) -> APR
A7: 46093 | B7: Canvas | C7: =TRIM(PROPER(ShoeSales[[#This Row],[Product]])) -> Canvas | D7: Utility | E7: =UPPER(ShoeSales[[#This Row],[Category]]) -> UTILITY | F7: Blue | G7: NIKE | H7: =PROPER(ShoeSales[[#This Row],[Brand]]) -> Nike | I7: Ghana | J7: 6 | K7: Card | L7: =VLOOKUP(ShoeSales[[#This Row],[Product Cleaned]],Price!$A$2:$C$9,2,FALSE) -> 128 | M7: =_xlfn.XLOOKUP(ShoeSales[[#This Row],[Product Cleaned]],Price!$A$2:$A$9,Price!$B$2:$B$9) -> 128 | N7: =_xlfn.XLOOKUP(ShoeSales[[#This Row],[Product Cleaned]],Price!$A$2:$A$9,Price!$C$2:$C$9) -> 72 | O7: =ShoeSales[[#This Row],[Sell Price]]*ShoeSales[[#This Row],[Quantity]] -> 768 | P7: =ShoeSales[[#This Row],[Quantity]]*ShoeSales[[#This Row],[Cost Price]] -> 432 | Q7: =ShoeSales[[#This Row],[Revenue]]-ShoeSales[[#This Row],[Cost]] -> 336 | R7: =ShoeSales[[#This Row],[Profit]]/ShoeSales[[#This Row],[Revenue]] -> 0.4375 | T7: =UPPER(TEXT(ShoeSales[[#This Row],[Date]], "mmm")) -> MAR
A8: 46191 | B8: canvas | C8: =TRIM(PROPER(ShoeSales[[#This Row],[Product]])) -> Canvas | D8: Formal | E8: =UPPER(ShoeSales[[#This Row],[Category]]) -> FORMAL | F8: Green | G8: clarks | H8: =PROPER(ShoeSales[[#This Row],[Brand]]) -> Clarks | I8: USA | J8: 13 | K8: Cash | L8: =VLOOKUP(ShoeSales[[#This Row],[Product Cleaned]],Price!$A$2:$C$9,2,FALSE) -> 128 | M8: =_xlfn.XLOOKUP(ShoeSales[[#This Row],[Product Cleaned]],Price!$A$2:$A$9,Price!$B$2:$B$9) -> 128 | N8: =_xlfn.XLOOKUP(ShoeSales[[#This Row],[Product Cleaned]],Price!$A$2:$A$9,Price!$C$2:$C$9) -> 72 | O8: =ShoeSales[[#This Row],[Sell Price]]*ShoeSales[[#This Row],[Quantity]] -> 1664 | P8: =ShoeSales[[#This Row],[Quantity]]*ShoeSales[[#This Row],[Cost Price]] -> 936 | Q8: =ShoeSales[[#This Row],[Revenue]]-ShoeSales[[#This Row],[Cost]] -> 728 | R8: =ShoeSales[[#This Row],[Profit]]/ShoeSales[[#This Row],[Revenue]] -> 0.4375 | T8: =UPPER(TEXT(ShoeSales[[#This Row],[Date]], "mmm")) -> JUN
A9: 46212 | B9: monk straps | C9: =TRIM(PROPER(ShoeSales[[#This Row],[Product]])) -> Monk Straps | D9: Formal | E9: =UPPER(ShoeSales[[#This Row],[Category]]) -> FORMAL | F9: Brown | G9: timberland | H9: =PROPER(ShoeSales[[#This Row],[Brand]]) -> Timberland | I9: USA | J9: 12 | K9: Cash | L9: =VLOOKUP(ShoeSales[[#This Row],[Product Cleaned]],Price!$A$2:$C$9,2,FALSE) -> 89 | M9: =_xlfn.XLOOKUP(ShoeSales[[#This Row],[Product Cleaned]],Price!$A$2:$A$9,Price!$B$2:$B$9) -> 89 | N9: =_xlfn.XLOOKUP(ShoeSales[[#This Row],[Product Cleaned]],Price!$A$2:$A$9,Price!$C$2:$C$9) -> 47 | O9: =ShoeSales[[#This Row],[Sell Price]]*ShoeSales[[#This Row],[Quantity]] -> 1068 | P9: =ShoeSales[[#This Row],[Quantity]]*ShoeSales[[#This Row],[Cost Price]] -> 564 | Q9: =ShoeSales[[#This Row],[Revenue]]-ShoeSales[[#This Row],[Cost]] -> 504 | R9: =ShoeSales[[#This Row],[Profit]]/ShoeSales[[#This Row],[Revenue]] -> 0.47191011 | T9: =UPPER(TEXT(ShoeSales[[#This Row],[Date]], "mmm")) -> JUL
A10: 46038 | B10: Derby | C10: =TRIM(PROPER(ShoeSales[[#This Row],[Product]])) -> Derby | D10: formal | E10: =UPPER(ShoeSales[[#This Row],[Category]]) -> FORMAL | F10: Green | G10: clarks | H10: =PROPER(ShoeSales[[#This Row],[Brand]]) -> Clarks | I10: Australia | J10: 10 | K10: Cash | L10: =VLOOKUP(ShoeSales[[#This Row],[Product Cleaned]],Price!$A$2:$C$9,2,FALSE) -> 32 | M10: =_xlfn.XLOOKUP(ShoeSales[[#This Row],[Product Cleaned]],Price!$A$2:$A$9,Price!$B$2:$B$9) -> 32 | N10: =_xlfn.XLOOKUP(ShoeSales[[#This Row],[Product Cleaned]],Price!$A$2:$A$9,Price!$C$2:$C$9) -> 14 | O10: =ShoeSales[[#This Row],[Sell Price]]*ShoeSales[[#This Row],[Quantity]] -> 320 | P10: =ShoeSales[[#This Row],[Quantity]]*ShoeSales[[#This Row],[Cost Price]] -> 140 | Q10: =ShoeSales[[#This Row],[Revenue]]-ShoeSales[[#This Row],[Cost]] -> 180 | R10: =ShoeSales[[#This Row],[Profit]]/ShoeSales[[#This Row],[Revenue]] -> 0.5625 | T10: =UPPER(TEXT(ShoeSales[[#This Row],[Date]], "mmm")) -> JAN
A11: 46182 | B11: OXFORD | C11: =TRIM(PROPER(ShoeSales[[#This Row],[Product]])) -> Oxford | D11: Formal | E11: =UPPER(ShoeSales[[#This Row],[Category]]) -> FORMAL | F11: Black | G11: clarks | H11: =PROPER(ShoeSales[[#This Row],[Brand]]) -> Clarks | I11: Cyprus | J11: 15 | K11: Mobile Money | L11: =VLOOKUP(ShoeSales[[#This Row],[Product Cleaned]],Price!$A$2:$C$9,2,FALSE) -> 105 | M11: =_xlfn.XLOOKUP(ShoeSales[[#This Row],[Product Cleaned]],Price!$A$2:$A$9,Price!$B$2:$B$9) -> 105 | N11: =_xlfn.XLOOKUP(ShoeSales[[#This Row],[Product Cleaned]],Price!$A$2:$A$9,Price!$C$2:$C$9) -> 58 | O11: =ShoeSales[[#This Row],[Sell Price]]*ShoeSales[[#This Row],[Quantity]] -> 1575 | P11: =ShoeSales[[#This Row],[Quantity]]*ShoeSales[[#This Row],[Cost Price]] -> 870 | Q11: =ShoeSales[[#This Row],[Revenue]]-ShoeSales[[#This Row],[Cost]] -> 705 | R11: =ShoeSales[[#This Row],[Profit]]/ShoeSales[[#This Row],[Revenue]] -> 0.44761905 | T11: =UPPER(TEXT(ShoeSales[[#This Row],[Date]], "mmm")) -> JUN
A12: 46132 | B12: BOOTS | C12: =TRIM(PROPER(ShoeSales[[#This Row],[Product]])) -> Boots | D12: Formal | E12: =UPPER(ShoeSales[[#This Row],[Category]]) -> FORMAL | F12: Brown | G12: Clarks | H12: =PROPER(ShoeSales[[#This Row],[Brand]]) -> Clarks | I12: India | J12: 8 | K12: Bank Transfer | L12: =VLOOKUP(ShoeSales[[#This Row],[Product Cleaned]],Price!$A$2:$C$9,2,FALSE) -> 76 | M12: =_xlfn.XLOOKUP(ShoeSales[[#This Row],[Product Cleaned]],Price!$A$2:$A$9,Price!$B$2:$B$9) -> 76 | N12: =_xlfn.XLOOKUP(ShoeSales[[#This Row],[Product Cleaned]],Price!$A$2:$A$9,Price!$C$2:$C$9) -> 39 | O12: =ShoeSales[[#This Row],[Sell Price]]*ShoeSales[[#This Row],[Quantity]] -> 608 | P12: =ShoeSales[[#This Row],[Quantity]]*ShoeSales[[#This Row],[Cost Price]] -> 312 | Q12: =ShoeSales[[#This Row],[Revenue]]-ShoeSales[[#This Row],[Cost]] -> 296 | R12: =ShoeSales[[#This Row],[Profit]]/ShoeSales[[#This Row],[Revenue]] -> 0.48684211 | T12: =UPPER(TEXT(ShoeSales[[#This Row],[Date]], "mmm")) -> APR
A13: 46097 | B13: loafers | C13: =TRIM(PROPER(ShoeSales[[#This Row],[Product]])) -> Loafers | D13: casual | E13: =UPPER(ShoeSales[[#This Row],[Category]]) -> CASUAL | F13: Green | G13: Clarks | H13: =PROPER(ShoeSales[[#This Row],[Brand]]) -> Clarks | I13: Australia | J13: 9 | K13: Cash | L13: =VLOOKUP(ShoeSales[[#This Row],[Product Cleaned]],Price!$A$2:$C$9,2,FALSE) -> 54 | M13: =_xlfn.XLOOKUP(ShoeSales[[#This Row],[Product Cleaned]],Price!$A$2:$A$9,Price!$B$2:$B$9) -> 54 | N13: =_xlfn.XLOOKUP(ShoeSales[[#This Row],[Product Cleaned]],Price!$A$2:$A$9,Price!$C$2:$C$9) -> 28 | O13: =ShoeSales[[#This Row],[Sell Price]]*ShoeSales[[#This Row],[Quantity]] -> 486 | P13: =ShoeSales[[#This Row],[Quantity]]*ShoeSales[[#This Row],[Cost Price]] -> 252 | Q13: =ShoeSales[[#This Row],[Revenue]]-ShoeSales[[#This Row],[Cost]] -> 234 | R13: =ShoeSales[[#This Row],[Profit]]/ShoeSales[[#This Row],[Revenue]] -> 0.48148148 | T13: =UPPER(TEXT(ShoeSales[[#This Row],[Date]], "mmm")) -> MAR
A14: 46146 | B14: BROGUES | C14: =TRIM(PROPER(ShoeSales[[#This Row],[Product]])) -> Brogues | D14: UTILITY | E14: =UPPER(ShoeSales[[#This Row],[Category]]) -> UTILITY | F14: Green | G14: Nike | H14: =PROPER(ShoeSales[[#This Row],[Brand]]) -> Nike | I14: Germany | J14: 14 | K14: Bank Transfer | L14: =VLOOKUP(ShoeSales[[#This Row],[Product Cleaned]],Price!$A$2:$C$9,2,FALSE) -> 112 | M14: =_xlfn.XLOOKUP(ShoeSales[[#This Row],[Product Cleaned]],Price!$A$2:$A$9,Price!$B$2:$B$9) -> 112 | N14: =_xlfn.XLOOKUP(ShoeSales[[#This Row],[Product Cleaned]],Price!$A$2:$A$9,Price!$C$2:$C$9) -> 64 | O14: =ShoeSales[[#This Row],[Sell Price]]*ShoeSales[[#This Row],[Quantity]] -> 1568 | P14: =ShoeSales[[#This Row],[Quantity]]*ShoeSales[[#This Row],[Cost Price]] -> 896 | Q14: =ShoeSales[[#This Row],[Revenue]]-ShoeSales[[#This Row],[Cost]] -> 672 | R14: =ShoeSales[[#This Row],[Profit]]/ShoeSales[[#This Row],[Revenue]] -> 0.42857143 | T14: =UPPER(TEXT(ShoeSales[[#This Row],[Date]], "mmm")) -> MAY
A15: 46031 | B15: oxford | C15: =TRIM(PROPER(ShoeSales[[#This Row],[Product]])) -> Oxford | D15: formal | E15: =UPPER(ShoeSales[[#This Row],[Category]]) -> FORMAL | F15: Green | G15: timberland | H15: =PROPER(ShoeSales[[#This Row],[Brand]]) -> Timberland | I15: Nigeria | J15: 4 | K15: Card | L15: =VLOOKUP(ShoeSales[[#This Row],[Product Cleaned]],Price!$A$2:$C$9,2,FALSE) -> 105 | M15: =_xlfn.XLOOKUP(ShoeSales[[#This Row],[Product Cleaned]],Price!$A$2:$A$9,Price!$B$2:$B$9) -> 105 | N15: =_xlfn.XLOOKUP(ShoeSales[[#This Row],[Product Cleaned]],Price!$A$2:$A$9,Price!$C$2:$C$9) -> 58 | O15: =ShoeSales[[#This Row],[Sell Price]]*ShoeSales[[#This Row],[Quantity]] -> 420 | P15: =ShoeSales[[#This Row],[Quantity]]*ShoeSales[[#This Row],[Cost Price]] -> 232 | Q15: =ShoeSales[[#This Row],[Revenue]]-ShoeSales[[#This Row],[Cost]] -> 188 | R15: =ShoeSales[[#This Row],[Profit]]/ShoeSales[[#This Row],[Revenue]] -> 0.44761905 | T15: =UPPER(TEXT(ShoeSales[[#This Row],[Date]], "mmm")) -> JAN
A16: 46199 | B16: SLIPPERS | C16: =TRIM(PROPER(ShoeSales[[#This Row],[Product]])) -> Slippers | D16: FORMAL | E16: =UPPER(ShoeSales[[#This Row],[Category]]) -> FORMAL | F16: Red | G16: ZARA | H16: =PROPER(ShoeSales[[#This Row],[Brand]]) -> Zara | I16: Uganda | J16: 6 | K16: Card | L16: =VLOOKUP(ShoeSales[[#This Row],[Product Cleaned]],Price!$A$2:$C$9,2,FALSE) -> 119 | M16: =_xlfn.XLOOKUP(ShoeSales[[#This Row],[Product Cleaned]],Price!$A$2:$A$9,Price!$B$2:$B$9) -> 119 | N16: =_xlfn.XLOOKUP(ShoeSales[[#This Row],[Product Cleaned]],Price!$A$2:$A$9,Price!$C$2:$C$9) -> 67 | O16: =ShoeSales[[#This Row],[Sell Price]]*ShoeSales[[#This Row],[Quantity]] -> 714 | P16: =ShoeSales[[#This Row],[Quantity]]*ShoeSales[[#This Row],[Cost Price]] -> 402 | Q16: =ShoeSales[[#This Row],[Revenue]]-ShoeSales[[#This Row],[Cost]] -> 312 | R16: =ShoeSales[[#This Row],[Profit]]/ShoeSales[[#This Row],[Revenue]] -> 0.43697479 | T16: =UPPER(TEXT(ShoeSales[[#This Row],[Date]], "mmm")) -> JUN
A17: 46226 | B17: derby | C17: =TRIM(PROPER(ShoeSales[[#This Row],[Product]])) -> Derby | D17: Casual | E17: =UPPER(ShoeSales[[#This Row],[Category]]) -> CASUAL | F17: Green | G17: Zara | H17: =PROPER(ShoeSales[[#This Row],[Brand]]) -> Zara | I17: Philippines | J17: 10 | K17: Cash | L17: =VLOOKUP(ShoeSales[[#This Row],[Product Cleaned]],Price!$A$2:$C$9,2,FALSE) -> 32 | M17: =_xlfn.XLOOKUP(ShoeSales[[#This Row],[Product Cleaned]],Price!$A$2:$A$9,Price!$B$2:$B$9) -> 32 | N17: =_xlfn.XLOOKUP(ShoeSales[[#This Row],[Product Cleaned]],Price!$A$2:$A$9,Price!$C$2:$C$9) -> 14 | O17: =ShoeSales[[#This Row],[Sell Price]]*ShoeSales[[#This Row],[Quantity]] -> 320 | P17: =ShoeSales[[#This Row],[Quantity]]*ShoeSales[[#This Row],[Cost Price]] -> 140 | Q17: =ShoeSales[[#This Row],[Revenue]]-ShoeSales[[#This Row],[Cost]] -> 180 | R17: =ShoeSales[[#This Row],[Profit]]/ShoeSales[[#This Row],[Revenue]] -> 0.5625 | T17: =UPPER(TEXT(ShoeSales[[#This Row],[Date]], "mmm")) -> JUL
A18: 46125 | B18: boots | C18: =TRIM(PROPER(ShoeSales[[#This Row],[Product]])) -> Boots | D18: OPEN | E18: =UPPER(ShoeSales[[#This Row],[Category]]) -> OPEN | F18: Red | G18: Steve Madden | H18: =PROPER(ShoeSales[[#This Row],[Brand]]) -> Steve Madden | I18: Nigeria | J18: 7 | K18: Bank Transfer | L18: =VLOOKUP(ShoeSales[[#This Row],[Product Cleaned]],Price!$A$2:$C$9,2,FALSE) -> 76 | M18: =_xlfn.XLOOKUP(ShoeSales[[#This Row],[Product Cleaned]],Price!$A$2:$A$9,Price!$B$2:$B$9) -> 76 | N18: =_xlfn.XLOOKUP(ShoeSales[[#This Row],[Product Cleaned]],Price!$A$2:$A$9,Price!$C$2:$C$9) -> 39 | O18: =ShoeSales[[#This Row],[Sell Price]]*ShoeSales[[#This Row],[Quantity]] -> 532 | P18: =ShoeSales[[#This Row],[Quantity]]*ShoeSales[[#This Row],[Cost Price]] -> 273 | Q18: =ShoeSales[[#This Row],[Revenue]]-ShoeSales[[#This Row],[Cost]] -> 259 | R18: =ShoeSales[[#This Row],[Profit]]/ShoeSales[[#This Row],[Revenue]] -> 0.48684211 | T18: =UPPER(TEXT(ShoeSales[[#This Row],[Date]], "mmm")) -> APR
... A501: 46218 | B501: Derby | C501: =TRIM(PROPER(ShoeSales[[#This Row],[Product]])) -> Derby | D501: casual | E501: =UPPER(ShoeSales[[#This Row],[Category]]) -> CASUAL | F501: Red | G501: CLARKS | H501: =PROPER(ShoeSales[[#This Row],[Brand]]) -> Clarks | I501: Germany | J501: 4 | K501: Bank Transfer | L501: =VLOOKUP(ShoeSales[[#This Row],[Product Cleaned]],Price!$A$2:$C$9,2,FALSE) -> 32 | M501: =_xlfn.XLOOKUP(ShoeSales[[#This Row],[Product Cleaned]],Price!$A$2:$A$9,Price!$B$2:$B$9) -> 32 | N501: =_xlfn.XLOOKUP(ShoeSales[[#This Row],[Product Cleaned]],Price!$A$2:$A$9,Price!$C$2:$C$9) -> 14 | O501: =ShoeSales[[#This Row],[Sell Price]]*ShoeSales[[#This Row],[Quantity]] -> 128 | P501: =ShoeSales[[#This Row],[Quantity]]*ShoeSales[[#This Row],[Cost Price]] -> 56 | Q501: =ShoeSales[[#This Row],[Revenue]]-ShoeSales[[#This Row],[Cost]] -> 72 | R501: =ShoeSales[[#This Row],[Profit]]/ShoeSales[[#This Row],[Revenue]] -> 0.5625 | T501: =UPPER(TEXT(ShoeSales[[#This Row],[Date]], "mmm")) -> JUL

Sheet Pivot Tables
B3: Total Revenue | C3: Total Cost | D3: Total Profit | E3: Avg Profit Margin | F3: Quantity Sold | G3: No of Brands
B4: 355048 | C4: 192713 | D4: 162335 | E4: 0.47075624 | F4: 4012 | G4: 5
B5: =GETPIVOTDATA("Total Revenue",$B$3) -> 355048 | C5: =GETPIVOTDATA("Total Cost",$B$3) -> 192713 | D5: =GETPIVOTDATA("Total Profit",$B$3) -> 162335 | E5: =GETPIVOTDATA("Avg Profit Margin",$B$3) -> 0.47075624 | F5: =GETPIVOTDATA("Quantity Sold",$B$3) -> 4012 | G5: =GETPIVOTDATA("No of Brands",$B$3) -> 5
B7: Months | C7: Revenue | L7: Row Labels | M7: Sum of Revenue
B8: Jan | C8: 43801 | L8: January | M8: 43801
B9: Feb | C9: 40664 | L9: February | M9: 40664
B10: Mar | C10: 45492 | L10: March | M10: 45492
B11: Apr | C11: 44204 | L11: April | M11: 44204
B12: May | C12: 44578 | L12: May | M12: 44578
B13: Jun | C13: 70771 | L13: June | M13: 70771
B14: Jul | C14: 49497 | L14: July | M14: 49497
B15: Aug | C15: 16041 | L15: August | M15: 16041
B16: Grand Total | C16: 355048 | L16: Grand Total | M16: 355048
B24: Products | C24: Revenue
B25: Boots | C25: 41040
B26: Brogues | C26: 58576
B27: Canvas | C27: 63488
B28: Derby | C28: 16704
B29: Loafers | C29: 24462
B30: Monk Straps | C30: 51175
B31: Oxford | C31: 58905
B32: Slippers | C32: 40698
B33: Grand Total | C33: 355048
B41: Category | C41: Revenue
B42: CASUAL | C42: 82917
B43: FORMAL | C43: 179935
B44: OPEN | C44: 53035
B45: UTILITY | C45: 39161
B46: Grand Total | C46: 355048
B58: Brand | C58: Revenue
B59: Clarks | C59: 123543
B60: Nike | C60: 54029
B61: Steve Madden | C61: 43855
B62: Timberland | C62: 38824
B63: Zara | C63: 94797
B64: Grand Total | C64: 355048
B75: Country | C75: Profit | D75: Revenue
B76: USA | C76: 17892 | D76: 39127 | M76: =B76 -> USA | N76: =C76 -> 17892 | O76: =D76 -> 39127
B77: UK | C77: 15393 | D77: 32871
B78: Ghana | C78: 14468 | D78: 32026
...

Sheet Business Questions
A2: Business Questions:
A3: 1. How is the business performing overall?
A4: 2. How have revenue and profit changed over time?
A5: 3. Which products are driving sales?
A6: 4. Which products are driving profitability?
A7: 5. Which categories and brands perform best?
A8: 6. Which countries contribute the most to the business?
A9: 7. What purchasing patterns can we identify from payment method and product preferences?
A10: 8. What actions should management take based on the findings?

Sheet Shoe_Sale Power Query
A1: Date | B1: Product | C1: Category | D1: Color | E1: Brand | F1: Country | G1: Quantity | H1: Payment Type
A2: 46161 | B2: Monk Straps | C2: Formal | D2: Red | E2: Nike | F2: Uganda | G2: 7 | H2: Bank Transfer
A3: 46199 | B3: Loafers | C3: Formal | D3: Black | E3: Nike | F3: Uganda | G3: 1 | H3: Card
A4: 46172 | B4: Derby | C4: Formal | D4: Green | E4: Clarks | F4: Nigeria | G4: 7 | H4: Bank Transfer
A5: 46214 | B5: Boots | C5: Utility | D5: Black | E5: Nike | F5: Canada | G5: 6 | H5: Bank Transfer
A6: 46130 | B6: Boots | C6: Casual | D6: Red | E6: Clarks | F6: UK | G6: 6 | H6: Bank Transfer
A7: 46093 | B7: Canvas | C7: Utility | D7: Blue | E7: Nike | F7: Ghana | G7: 6 | H7: Card
A8: 46191 | B8: Canvas | C8: Formal | D8: Green | E8: Clarks | F8: USA | G8: 13 | H8: Cash
A9: 46212 | B9: Monk Straps | C9: Formal | D9: Brown | E9: Timberland | F9: USA | G9: 12 | H9: Cash
A10: 46038 | B10: Derby | C10: Formal | D10: Green | E10: Clarks | F10: Australia | G10: 10 | H10: Cash
A11: 46182 | B11: Oxford | C11: Formal | D11: Black | E11: Clarks | F11: Cyprus | G11: 15 | H11: Mobile Money
A12: 46132 | B12: Boots | C12: Formal | D12: Brown | E12: Clarks | F12: India | G12: 8 | H12: Bank Transfer
A13: 46097 | B13: Loafers | C13: Casual | D13: Green | E13: Clarks | F13: Australia | G13: 9 | H13: Cash
... A501: 46218 | B501: Derby | C501: Casual | D501: Red | E501: Clarks | F501: Germany | G501: 4 | H501: Bank Transfer

Sheet Shoe Sales
A1: Date | B1: Product | C1: Category | D1: Color | E1: Brand | F1: Country | G1: Quantity | H1: Payment Type
A2: 46161 | B2: monk straps | C2: Formal | D2: Red | E2: Nike | F2: Uganda | G2: 7 | H2: Bank Transfer
A3: 46199 | B3: loafers | C3: Formal | D3: Black | E3: nike | F3: Uganda | G3: 1 | H3: Card
A4: 46172 | B4: Derby | C4: FORMAL | D4: Green | E4: clarks | F4: Nigeria | G4: 7 | H4: Bank Transfer
A5: 46214 | B5: boots | C5: UTILITY | D5: Black | E5: nike | F5: Canada | G5: 6 | H5: Bank Transfer
A6: 46130 | B6: BOOTS | C6: casual | D6: Red | E6: CLARKS | F6: UK | G6: 6 | H6: Bank Transfer
A7: 46093 | B7: Canvas | C7: Utility | D7: Blue | E7: NIKE | F7: Ghana | G7: 6 | H7: Card
A8: 46191 | B8: canvas | C8: Formal | D8: Green | E8: clarks | F8: USA | G8: 13 | H8: Cash
A9: 46212 | B9: monk straps | C9: Formal | D9: Brown | E9: timberland | F9: USA | G9: 12 | H9: Cash
A10: 46038 | B10: Derby | C10: formal | D10: Green | E10: clarks | F10: Australia | G10: 10 | H10: Cash
A11: 46182 | B11: OXFORD | C11: Formal | D11: Black | E11: clarks | F11: Cyprus | G11: 15 | H11: Mobile Money
A12: 46132 | B12: BOOTS | C12: Formal | D12: Brown | E12: Clarks | F12: India | G12: 8 | H12: Bank Transfer
A13: 46097 | B13: loafers | C13: casual | D13: Green | E13: Clarks | F13: Australia | G13: 9 | H13: Cash
... A501: 46218 | B501: Derby | C501: casual | D501: Red | E501: CLARKS | F501: Germany | G501: 4 | H501: Bank Transfer

Sheet Price
A1: Product | B1: Price | C1: Cost
A2: Monk Straps | B2: 89 | C2: 47
A3: Loafers | B3: 54 | C3: 28
A4: Derby | B4: 32 | C4: 14
A5: Boots | B5: 76 | C5: 39
A6: Canvas | B6: 128 | C6: 72
A7: Oxford | B7: 105 | C7: 58
A8: Brogues | B8: 112 | C8: 64
A9: Slippers | B9: 119 | C9: 67
